Exception in thread Thread-6:
Traceback (most recent call last):
  File "/usr/lib64/python3.6/threading.py", line 916, in _bootstrap_inner
    self.run()
  File "/usr/lib64/python3.6/threading.py", line 864, in run
    self._target(*self._args, **self._kwargs)
  File "stockAnalytics.py", line 56, in collectStockPrices
    self.writeCSVFile()
  File "stockAnalytics.py", line 44, in writeCSVFile
    stockLabelFile.writerow([self.getStockPrice(), dt_string, month, day, year])
  File "stockAnalytics.py", line 27, in getStockPrice
    return bsoup(self.getPage(),"html.parser").find('div', {'class':'My(6px) Pos(r) smartphone_Mt(6px)'}).find('span').get_text()
  File "stockAnalytics.py", line 24, in getPage
    return urlopen(self.url)
  File "/usr/lib64/python3.6/urllib/request.py", line 223, in urlopen
    return opener.open(url, data, timeout)
  File "/usr/lib64/python3.6/urllib/request.py", line 532, in open
    response = meth(req, response)
  File "/usr/lib64/python3.6/urllib/request.py", line 642, in http_response
    'http', request, response, code, msg, hdrs)
  File "/usr/lib64/python3.6/urllib/request.py", line 564, in error
    result = self._call_chain(*args)
  File "/usr/lib64/python3.6/urllib/request.py", line 504, in _call_chain
    result = func(*args)
  File "/usr/lib64/python3.6/urllib/request.py", line 756, in http_error_302
    return self.parent.open(new, timeout=req.timeout)
  File "/usr/lib64/python3.6/urllib/request.py", line 532, in open
    response = meth(req, response)
  File "/usr/lib64/python3.6/urllib/request.py", line 642, in http_response
    'http', request, response, code, msg, hdrs)
  File "/usr/lib64/python3.6/urllib/request.py", line 570, in error
    return self._call_chain(*args)
  File "/usr/lib64/python3.6/urllib/request.py", line 504, in _call_chain
    result = func(*args)
  File "/usr/lib64/python3.6/urllib/request.py", line 650, in http_error_default
    raise HTTPError(req.full_url, code, msg, hdrs, fp)
urllib.error.HTTPError: HTTP Error 503: Service Unavailable
